Workbook

Sheet Intro

Sheet Balance Sheet
A1: Particulars | B1: Notes | C1: 45747 | D1: 45382 | E1: 45016 | F1: 44651 | G1: 44286 | H1: 43921 | I1: (₹ in Millions)
A2: ASSETS
A3: Non-current assets
A4: Property, plant and equipment | B4: 3 | C4: 1771.09 | D4: 1967.33 | E4: 2249.12 | F4: 2456.54 | G4: 2117.82 | H4: 1699.74
A5: Capital work-in-progress | B5: 3 | C5: 1.82 | D5: 136.93 | E5: 54.6 | F5: 109.84 | G5: 31.27 | H5: 73.8
A6: Right-of-use assets | B6: 4 | C6: 6444.73 | D6: 7248.1 | E6: 7469 | F6: 6236.31 | G6: 5677.15 | H6: 6236.41
A7: Goodwill | B7: 5 | C7: 42907.06 | D7: 41792.68 | E7: 29585.89 | F7: 27348.06 | G7: 21325.67 | H7: 21404.74
A8: Other intangible assets | B8: 7 | C8: 6691.92 | D8: 4318.16 | E8: 1293.95 | F8: 1695.39 | G8: 1074.48 | H8: 794.04
A9: Intangible assets under development | B9: 7a | C9: - | D9: 477.46 | E9: 269.24 | F9: - | G9: - | H9: 93.22
A10: Financial assets
A11: (i) Investments | B11: 8 | C11: 4237.77 | D11: 4971.41 | E11: 3847.61 | F11: 3778.01 | G11: 3114.28 | H11: 3478.7
A12: (ii) Trade receivables | B12: 13 | C12: 3196.76 | D12: 2771.84 | E12: 1333.66 | F12: - | G12: - | H12: -
A13: (iii) Loans | B13: 9 | C13: - | D13: - | E13: - | F13: - | G13: 547.17 | H13: 640.68
A14: (iv) Other financial assets | B14: 10 | C14: 1752.33 | D14: 710.95 | E14: 717.61 | F14: 998.46 | G14: 928.75 | H14: 164.71
A15: Deferred tax assets (net) | B15: 23/24 | C15: 3246.1 | D15: 2856.51 | E15: 2422.4 | F15: 1616.11 | G15: 1260.72 | H15: 2157.46
A16: Income/Other tax assets (net) | B16: 23/24 | C16: 7966.91 | D16: 6419.52 | E16: 5817.43 | F16: 5309.34 | G16: 5496.4 | H16: 4882.58
A17: Other assets | B17: 11 | C17: 988.6 | D17: 1307.42 | E17: 1503.83 | F17: 849.66 | G17: 1013.12 | H17: 1778.27
A18: Total non-current assets | C18: 79205.09 | D18: 74978.31 | E18: 56564.34 | F18: 50397.72 | G18: 42586.83 | H18: 43404.35
A20: Current assets
A21: Financial assets
A22: (i) Investments | B22: 12 | C22: 17844.25 | D22: 25927.7 | E22: 13678.81 | F22: 14352.11 | G22: 15345.9 | H22: 9777.8
A23: (ii) Trade receivables | B23: 13 | C23: 28407.25 | D23: 24255.63 | E23: 25206.32 | F23: - | G23: - | H23: 8352.52
A24: Billed receivables | C24: - | D24: - | E24: - | F24: 9681.48 | G24: 9294.82 | H24: -
A25: Unbilled receivables | C25: - | D25: - | E25: - | F25: 12587.88 | G25: 9210.05 | H25: 9343.02
A26: (iv) Cash and cash equivalents | B26: 14 | C26: 9863.45 | D26: 8049.14 | E26: 10441.13 | F26: 8268.47 | G26: 7711.44 | H26: 9880.01
A27: (v) Bank balances | B27: 15 | C27: 6262.35 | D27: 94.51 | E27: 93.31 | F27: 1225.9 | G27: 2910.98 | H27: 1377.02
A28: (vi) Loans | B28: 9 | C28: 385.56 | D28: 341.97 | E28: 287.54 | F28: 318.21 | G28: 1468.93 | H28: 1409.11
A29: (vii) Other financial assets | B29: 10 | C29: 1600.39 | D29: 1715.29 | E29: 1435.35 | F29: 2644.56 | G29: 1280.74 | H29: 548.05
A30: Other assets | B30: 11 | C30: 5497.95 | D30: 5939.83 | E30: 8387.79 | F30: 8085.11 | G30: 4179.79 | H30: 3443.03
A31: Total current assets | C31: 69861.2 | D31: 66324.07 | E31: 59530.25 | F31: 57163.72 | G31: 51402.65 | H31: 44130.56
A32: TOTAL ASSETS | C32: 149066.29 | D32: 141302.38 | E32: 116094.59 | F32: 107561.44 | G32: 93989.48 | H32: 87534.91
A33: --- | B33: --- | C33: --- | D33: --- | E33: --- | F33: --- | G33: --- | H33: ---
A34: EQUITY AND LIABILITIES
A35: EQUITY
A36: Share capital | B36: 16 | C36: 1900.84 | D36: 1890.05 | E36: 1884.07 | F36: 1878.25 | G36: 1870.49 | H36: 1865.43
A37: Other equity | B37: 17 | C37: 94383.12 | D37: 86055.95 | E37: 77464.32 | F37: 67553.06 | G37: 63396.61 | H37: 56430.56
A38: Total equity | C38: 96283.96 | D38: 87946 | E38: 79348.39 | F38: 69431.31 | G38: 65267.1 | H38: 58295.99
A40: Non-current liabilities
A41: Lease liabilities | C41: 5839.58 | D41: 6750.16 | E41: 6815.82 | F41: 5840.48 | G41: 5370.38 | H41: 5844.4
A42: Other financial liabilities | B42: 18 | C42: 305.16 | D42: 2422.99 | E42: 329.03 | F42: 1059.52 | G42: 39.69 | H42: 630.82
...

Sheet Income Statement
A1: Particulars | B1: 45747 | C1: 45382 | D1: 45016 | E1: 44651 | F1: 44286 | G1: 43921 | H1: (₹ in Millions)
A2: INCOME
A3: Revenue from operations | B3: 142299.87 | C3: 132785.15 | D3: 137984.97 | E3: 119614.44 | F3: 97223.11 | G3: 88435.37
A4: Other income | B4: 2550.01 | C4: 2178.04 | D4: 1615.99 | E4: 1604.5 | F4: 1329.45 | G4: 1778.2
A5: Total income (I) | B5: 144849.88 | C5: 134963.19 | D5: 139600.96 | E5: 121218.94 | F5: 98552.56 | G5: 90213.57
A7: EXPENSES
A8: Employee benefits expense | B8: 81446.59 | C8: 79253.27 | D8: 80757.8 | E8: 70345.01 | F8: 56297.86 | G8: 49226.41
A9: Finance costs | B9: 1655.01 | C9: 1608.67 | D9: 972.58 | E9: 744.03 | F9: 634.15 | G9: 811.93
A10: Depreciation and amortization | B10: 4763.37 | C10: 4104.99 | D10: 3252.42 | E10: 2907.52 | F10: 2417.88 | G10: 2316.31
A11: Other expenses | B11: 34383.48 | C11: 29313.04 | D11: 32887.59 | E11: 28093.38 | F11: 22896.59 | G11: 22705.12
A12: Total expenses (II) | B12: 122248.45 | C12: 114279.97 | D12: 117870.39 | E12: 102089.94 | F12: 82246.48 | G12: 75059.77
A14: Profit before tax (III) [(I)-(II)] | B14: 22601.43 | C14: 20683.22 | D14: 21730.57 | E14: 19129 | F14: 16306.08 | G14: 15153.8
A16: Tax expense
A17: Current tax | B17: 5535.16 | C17: 5775.9 | D17: 5078.68 | E17: 4859.65 | F17: 4094.3 | G17: 3495.35
A18: Deferred tax | B18: 44.88 | C18: -640.88 | D18: 272.67 | E18: -39.54 | F18: 43.73 | G18: -189.92
A19: Total tax expense | B19: 5580.04 | C19: 5135.02 | D19: 5351.35 | E19: 4820.11 | F19: 4138.03 | G19: 3305.43
A21: Profit for the year (A) | B21: 17021.39 | C21: 15548.2 | D21: 16379.22 | E21: 14308.89 | F21: 12168.05 | G21: 11848.37
A23: Other Comprehensive Income (B) | B23: 570.48 | C23: 1295.29 | D23: 630.26 | E23: 937.29 | F23: 962.72 | G23: 739.06
A25: Total Comprehensive Income (A+B) | B25: 17591.87 | C25: 16843.49 | D25: 17009.48 | E25: 15246.18 | F25: 13130.77 | G25: 12587.43
A27: Earnings per equity share (₹)
A28: Basic | B28: 89.87 | C28: 82.42 | D28: 87.05 | E28: 76.38 | F28: 65.18 | G28: 63.57
A29: Diluted | B29: 89.36 | C29: 81.83 | D29: 86.37 | E29: 75.61 | F29: 64.43 | G29: 63.09

Sheet Cashflow
A1: Particulars | B1: 45747 | C1: 45382 | D1: 45016 | E1: 44651 | F1: 44286 | G1: 43921 | H1: (₹ in Millions)
A2: Operating activities:
A3: Profit before tax | B3: 22601.43 | C3: 20683.22 | D3: 21730.57 | E3: 19129 | F3: 16306.08 | G3: 15153.8
A4: Adjustments to reconcile profit before tax to net cash provided by operating activities:
A5: Depreciation and amortization expense | B5: 4763.37 | C5: 4104.99 | D5: 3252.42 | E5: 2907.52 | F5: 2417.88 | G5: 2316.31
A6: Profit on sale of property, plant and equipment and intangible assets | B6: -17.97 | C6: -17.5 | D6: -18.14 | E6: -4.97 | F6: -4.31 | G6: -16.33
A7: Net gain on investments carried at fair value through profit and loss | B7: -1527.32 | C7: -1434.87 | D7: -734.61 | E7: -754.84 | F7: -839.28 | G7: -933.38
A8: Share based payment expenses | B8: 571.53 | C8: 881.68 | D8: 1289.22 | E8: 651.72 | F8: 102.19 | G8: 146.7
A9: Provision for expected credit loss | B9: 892.06 | C9: 310.71 | D9: 262.97 | E9: 106.89 | F9: 251.81 | G9: 92.49
A10: Finance costs | B10: 1655.01 | C10: 1608.67 | D10: 972.58 | E10: 744.03 | F10: 634.15 | G10: 811.93
A11: Interest income | B11: -927.23 | C11: -528.06 | D11: -350.35 | E11: -352.46 | F11: -213.25 | G11: -557.21
A12: Gain on lease modifications | B12: -24.95 | C12: -34.05 | D12: -16.66 | E12: - | F12: -31.82 | G12: -
A13: Provision for other assets | B13: 279.33 | C13: 139.01 | D13: - | E13: - | F13: - | G13: -
A14: Gain on reversal of contingent consideration | B14: - | C14: -2004.82 | D14: - | E14: - | F14: - | G14: -
A15: Others | B15: - | C15: - | D15: - | E15: - | F15: -106.41 | G15: -106.42
A16: Unrealized exchange loss / (gain), net | B16: 239.02 | C16: -37.85 | D16: -65.24 | E16: -82.64 | F16: -102.1 | G16: -160.04
A17: Operating profit before changes in operating assets and liabilities | B17: 28504.28 | C17: 23671.13 | D17: 26322.76 | E17: 22344.25 | F17: 18446.76 | G17: 16747.85
A18: Changes in operating assets and liabilities
A19: Trade receivables / Unbilled receivables | B19: -5225.11 | C19: 371.44 | D19: -3712.8 | E19: -3118 | F19: -820.64 | G19: 1779.25
A20: Loans | B20: -41.39 | C20: -52.88 | D20: 40.14 | E20: -155.26 | F20: 89.59 | G20: -209.43
A21: Other financial assets | B21: -120.06 | C21: -73.04 | D21: 45.26 | E21: 271.58 | F21: 139.43 | G21: -70.71
A22: Other assets | B22: 559.29 | C22: 3114.96 | D22: -861 | E22: -3603.2 | F22: -310.54 | G22: -832.49
A23: Trade payables | B23: 1651.14 | C23: -990.67 | D23: -327.43 | E23: 2401.76 | F23: -924.81 | G23: -1442.35
A24: Other financial liabilities | B24: 1321.34 | C24: 966.12 | D24: 463.4 | E24: 2220.15 | F24: -132.19 | G24: 678.09
A25: Other liabilities | B25: -503.84 | C25: -133.57 | D25: -660.68 | E25: -516.54 | F25: 899.59 | G25: 535.53
A26: Provisions and employee benefit obligations | B26: 17.48 | C26: 825.2 | D26: -765.75 | E26: 998.41 | F26: 606.38 | G26: -15.47
A27: Total changes in operating assets and liabilities | B27: -2341.15 | C27: 4027.56 | D27: -5778.86 | E27: -1501.1 | F27: -453.19 | G27: 422.42
A28: Income tax paid (net of refunds) | B28: -7111.11 | C28: -5901.72 | D28: -5926.25 | E28: -3685.83 | F28: -3448.25 | G28: -3960.06
A29: Net cash flows generated from operating activities (A) | B29: 19052.02 | C29: 21796.97 | D29: 14617.65 | E29: 17157.32 | F29: 14545.32 | G29: 13210.21
A31: Investing activities:
A32: Purchase of property, plant and equipment and intangible assets | B32: -618.39 | C32: -936.92 | D32: -1131.45 | E32: -1200.25 | F32: -1261.65 | G32: -1261.18
A33: Proceeds from sale of property, plant and equipment and intangible assets | B33: 19.71 | C33: 20.71 | D33: 19.93 | E33: 8.45 | F33: 9.76 | G33: 18.08
A34: Purchase of investments | B34: -90992.09 | C34: -76749.58 | D34: -80446.43 | E34: -58146.48 | F34: -67143.61 | G34: -78641.89
A35: Sale of investments | B35: 101478.52 | C35: 64851.45 | D35: 81800.68 | E35: 59231.38 | F35: 62779.21 | G35: 79610.98
A36: Interest received | B36: 463.26 | C36: 329.07 | D36: 286.02 | E36: 320.67 | F36: 196.67 | G36: 211.98
A37: Payment for business acquisition, net of cash acquired | B37: -2799.75 | C37: -12332.99 | D37: - | E37: -5218.8 | F37: -805.19 | G37: -
A38: Investments in bank deposits | B38: -7133.94 | C38: -420.94 | D38: -15.72 | E38: -486.61 | F38: -3788.01 | G38: -1426.24
A39: Redemption / maturity of bank deposits | B39: 23.26 | C39: 418.47 | D39: 1311.8 | E39: 2671.29 | F39: 1794.01 | G39: 2895.7
A40: Net cash flows generated from / (used in) investing activities (B) | B40: 440.58 | C40: -24820.73 | D40: 1824.83 | E40: -2820.35 | F40: -8218.81 | G40: 1407.43
A42: Financing activities:
...

Sheet FCFF & FCFE
A1: Particulars | B1: FY 25 | C1: FY 24 | D1: FY 23 | E1: FY 22 | F1: FY 21 | G1: FY 20 | H1: (₹ in Millions)
A2: PBT | B2: 22601.43 | C2: 20683.22 | D2: 21730.57 | E2: 19129 | F2: 16306.08 | G2: 15153.8
A3: Interest Paid | B3: =-Cashflow!B46 -> 963.59 | C3: =-Cashflow!C46 -> 833.35 | D3: =-Cashflow!D46 -> 491.8 | E3: =-Cashflow!E46 -> 276.13 | F3: =-Cashflow!F46 -> 619.65 | G3: =-Cashflow!G46 -> 779.89
A4: Other Income | B4: 2550.01 | C4: 2178.04 | D4: 1615.99 | E4: 1604.5 | F4: 1329.45 | G4: 1778.2
A5: EBIT | B5: =B2+B3-B4 -> 21015.01 | C5: =C2+C3-C4 -> 19338.53 | D5: =D2+D3-D4 -> 20606.38 | E5: =E2+E3-E4 -> 17800.63 | F5: =F2+F3-F4 -> 15596.28 | G5: =G2+G3-G4 -> 14155.49
A6: Effective Tax Rate (t) | B6: ='Income Statement'!B19 / 'Income Statement'!B14 -> 0.2468888 | C6: ='Income Statement'!C19 / 'Income Statement'!C14 -> 0.24826985 | D6: ='Income Statement'!D19 / 'Income Statement'!D14 -> 0.24625907 | E6: ='Income Statement'!E19 / 'Income Statement'!E14 -> 0.25197919 | F6: ='Income Statement'!F19 / 'Income Statement'!F14 -> 0.25377221 | G6: ='Income Statement'!G19 / 'Income Statement'!G14 -> 0.21812549
A7: NOPAT=EBIT(1-t) | B7: =B5*(1-B6) -> 15826.639 | C7: =C5*(1-C6) -> 14537.356 | D7: =D5*(1-D6) -> 15531.872 | E7: =E5*(1-E6) -> 13315.242 | F7: =F5*(1-F6) -> 11638.378 | G7: =G5*(1-G6) -> 11067.817
A9: Depretiation and Amortization | B9: 4763.37 | C9: 4104.99 | D9: 3252.42 | E9: 2907.52 | F9: 2417.88 | G9: 2316.31
A11: Change in Working Capital | B11: -2341.15 | C11: 4027.56 | D11: -5778.86 | E11: -1501.1 | F11: -453.19 | G11: 422.42
A12: Capex | B12: 618.39 | C12: 936.92 | D12: 1131.45 | E12: 1200.25 | F12: 1261.65 | G12: 1261.18
A14: FCFF | B14: =B7+B9+B11-B12 -> 17630.469 | C14: =C7+C9+C11-C12 -> 21732.986 | D14: =D7+D9+D11-D12 -> 11873.982 | E14: =E7+E9+E11-E12 -> 13521.412 | F14: =F7+F9+F11-F12 -> 12341.418 | G14: =G7+G9+G11-G12 -> 12545.367
A16: Net Income | B16: 17021.39 | C16: 15548.2 | D16: 16379.22 | E16: 14308.89 | F16: 12168.05 | G16: 11848.37
A17: Net Borrowings | B17: -4454.6 | C17: 12964.96 | D17: -3557.05 | E17: 32.3 | F17: -408.71 | G17: -223.64
A19: FCFE | B19: =B16+B9-B12+B11+B17 -> 14370.62 | C19: =C16+C9-C12+C11+C17 -> 35708.79 | D19: =D16+D9-D12+D11+D17 -> 9164.28 | E19: =E16+E9-E12+E11+E17 -> 14547.36 | F19: =F16+F9-F12+F11+F17 -> 12462.38 | G19: =G16+G9-G12+G11+G17 -> 13102.28
A21: Share Price (Mar-end) | B21: 2500.2 | C21: 2388.05 | D21: 1795.75 | E21: 3376.85 | F21: 1760.48 | G21: 675.65
A22: Shares Outstanding (M) | B22: 190.08 | C22: 189.01 | D22: 188.41 | E22: 187.83 | F22: 187.05 | G22: 186.54
A23: Market Cap | B23: 406124.93 | C23: 452111.92 | D23: 338054.64 | E23: 634865.4 | F23: 333663.53 | G23: 122043.8
A25: Long-Term Borrowings | B25: 17240.45 | C25: 13200.5 | D25: 5400.25 | E25: 8900.6 | F25: 7800.4 | G25: 9100.35
A26: Short-Term Borrowings | B26: 4945.38 | C26: 4219.93 | D26: 3400.33 | E26: 3218.44 | F26: 3241.62 | G26: 3853.5
A27: Total Debt | B27: 22185.83 | C27: 17420.43 | D27: 8800.58 | E27: 12119.04 | F27: 11042.02 | G27: 12953.85
A29: Equity Weight | B29: =B23/(B23+B27) -> 0.94820156 | C29: =C23/(C23+C27) -> 0.96289834 | D29: =D23/(D23+D27) -> 0.97462751 | E29: =E23/(E23+E27) -> 0.98126842 | F29: =F23/(F23+F27) -> 0.96796681 | G29: =G23/(G23+G27) -> 0.90404389
A30: Debt Weight | B30: =B27/(B23+B27) -> 0.051798442 | C30: =C27/(C23+C27) -> 0.037101661 | D30: =D27/(D23+D27) -> 0.025372488 | E30: =E27/(E23+E27) -> 0.018731579 | F30: =F27/(F23+F27) -> 0.032033195 | G30: =G27/(G23+G27) -> 0.095956115
A31: kd(pre tax) | B31: =B3/B27 -> 0.043432678 | C31: =C3/C27 -> 0.04783751 | D31: =D3/D27 -> 0.05588268 | E31: =E3/E27 -> 0.022784808 | F31: =F3/F27 -> 0.05611745 | G31: =G3/G27 -> 0.060205267
A32: kd(post tax) | B32: =B3/B27*(1-B6) -> 0.032709636 | C32: =C3/C27*(1-C6) -> 0.035960899 | D32: =D3/D27*(1-D6) -> 0.042121063 | E32: =E3/E27*(1-E6) -> 0.01704351 | F32: =F3/F27*(1-F6) -> 0.0418764 | G32: =G3/G27*(1-G6) -> 0.047072964

Sheet WACC
A1: Date | B1: Mphasis Close Price | C1: NIFTY 50 Closing Price | D1: MPHASIS Log Return | E1: NIFTY Log Return | F1: Fiscal Year | H1: Beta | I1: Fiscal Year | J1: Rf (Bond Yield) | K1: ERP | L1: Ke = Rf + β×ERP | M1: WACC
A2: 43922 | B2: 675.65 | C2: 8253.8 | D2: =LN(B3/B2) -> -0.0060122653 | E2: =LN(C3/C2) -> -0.020811641 | F2: =YEAR(A2) -> 2020 | H2: =SLOPE(D3:D1427, E3:E1427) -> 0.91795629 | I2: FY2020 | J2: 0.0614 | K2: 0.0767 | L2: =Table3[[#This Row],[Rf (Bond Yield)]]+H2*Table3[[#This Row],[ERP]] -> 0.13180725 | M2: =('FCFF & FCFE'!G29*L2)+('FCFF & FCFE'!G30*'FCFF & FCFE'!G32) -> 0.12367647
A3: 43924 | B3: 671.6 | C3: 8083.8 | D3: =LN(B4/B3) -> -0.0018629612 | E3: =LN(C4/C3) -> 0.084002906 | F3: =YEAR(A3) -> 2020 | I3: FY2021 | J3: 0.0617 | K3: 0.0769 | L3: =Table3[[#This Row],[Rf (Bond Yield)]]+H2*Table3[[#This Row],[ERP]] -> 0.13229084 | M3: =('FCFF & FCFE'!F29*L3)+('FCFF & FCFE'!F30*'FCFF & FCFE'!F32) -> 0.12939458
A4: 43928 | B4: 670.35 | C4: 8792.2 | D4: =LN(B5/B4) -> 0.0045395427 | E4: =LN(C5/C4) -> -0.0049541318 | F4: =YEAR(A4) -> 2020 | I4: FY2022 | J4: 0.0685 | K4: 0.0727 | L4: =Table3[[#This Row],[Rf (Bond Yield)]]+H2*Table3[[#This Row],[ERP]] -> 0.13523542 | M4: =('FCFF & FCFE'!E29*L4)+('FCFF & FCFE'!E30*'FCFF & FCFE'!E32) -> 0.1330215
A5: 43929 | B5: 673.4 | C5: 8748.75 | D5: =LN(B6/B5) -> 0.0032616782 | E5: =LN(C6/C5) -> 0.040670419 | F5: =YEAR(A5) -> 2020 | I5: FY2023 | J5: 0.0724 | K5: 0.0805 | L5: =Table3[[#This Row],[Rf (Bond Yield)]]+H2*Table3[[#This Row],[ERP]] -> 0.14629548 | M5: =('FCFF & FCFE'!D29*L5)+('FCFF & FCFE'!D30*'FCFF & FCFE'!D32) -> 0.14365232
A6: 43930 | B6: 675.6 | C6: 9111.9 | D6: =LN(B7/B6) -> -0.0075029138 | E6: =LN(C7/C6) -> -0.013040241 | F6: =YEAR(A6) -> 2020 | I6: FY2024 | J6: 0.0705 | K6: 0.0734 | L6: =Table3[[#This Row],[Rf (Bond Yield)]]+H2*Table3[[#This Row],[ERP]] -> 0.13787799 | M6: =('FCFF & FCFE'!C29*L6)+('FCFF & FCFE'!C30*'FCFF & FCFE'!C32) -> 0.1340967
A7: 43934 | B7: 670.55 | C7: 8993.85 | D7: =LN(B8/B7) -> 0.00037275879 | E7: =LN(C8/C7) -> -0.0076510699 | F7: =YEAR(A7) -> 2020 | I7: FY2025 | J7: 0.0665 | K7: 0.0708 | L7: =Table3[[#This Row],[Rf (Bond Yield)]]+H2*Table3[[#This Row],[ERP]] -> 0.13149131 | M7: =('FCFF & FCFE'!B29*L7)+('FCFF & FCFE'!B30*'FCFF & FCFE'!B32) -> 0.12637457
A8: 43936 | B8: 670.8 | C8: 8925.3 | D8: =LN(B9/B8) -> 0.023353671 | E8: =LN(C9/C8) -> 0.0075343166 | F8: =YEAR(A8) -> 2020
A9: 43937 | B9: 686.65 | C9: 8992.8 | D9: =LN(B10/B9) -> 0.056826636 | E9: =LN(C10/C9) -> 0.030008468 | F9: =YEAR(A9) -> 2020
A10: 43938 | B10: 726.8 | C10: 9266.75 | D10: =LN(B11/B10) -> 0.031288528 | E10: =LN(C11/C10) -> -0.00052891207 | F10: =YEAR(A10) -> 2020
A11: 43941 | B11: 749.9 | C11: 9261.85 | D11: =LN(B12/B11) -> -0.10108761 | E11: =LN(C12/C11) -> -0.030742474 | F11: =YEAR(A11) -> 2020
A12: 43942 | B12: 677.8 | C12: 8981.45 | D12: =LN(B13/B12) -> -0.005696335 | E12: =LN(C13/C12) -> 0.022660756 | F12: =YEAR(A12) -> 2020
A13: 43943 | B13: 673.95 | C13: 9187.3 | D13: =LN(B14/B13) -> 0.031906339 | E13: =LN(C14/C13) -> 0.013685812 | F13: =YEAR(A13) -> 2020
A14: 43944 | B14: 695.8 | C14: 9313.9 | D14: =LN(B15/B14) -> -0.032351575 | E14: =LN(C15/C14) -> -0.01727327 | F14: =YEAR(A14) -> 2020
A15: 43945 | B15: 673.65 | C15: 9154.4 | D15: =LN(B16/B15) -> 0.035794906 | E15: =LN(C16/C15) -> 0.013874723 | F15: =YEAR(A15) -> 2020
A16: 43948 | B16: 698.2 | C16: 9282.3 | D16: =LN(B17/B16) -> 0.02034449 | E16: =LN(C17/C16) -> 0.010566346 | F16: =YEAR(A16) -> 2020
A17: 43949 | B17: 712.55 | C17: 9380.9 | D17: =LN(B18/B17) -> -0.0088100087 | E17: =LN(C18/C17) -> 0.018216171 | F17: =YEAR(A17) -> 2020
A18: 43950 | B18: 706.3 | C18: 9553.35 | D18: =LN(B19/B18) -> 0.031153431 | E18: =LN(C19/C18) -> 0.031584148 | F18: =YEAR(A18) -> 2020
A19: 43951 | B19: 728.65 | C19: 9859.9 | D19: =LN(B20/B19) -> -0.038970967 | E19: =LN(C20/C19) -> -0.059160796 | F19: =YEAR(A19) -> 2020
... A1427: 46021 | B1427: 2795.7 | C1427: 25938.85 | D1427: =LN(B1428/B1427) -> -0.0016109116 | E1427: =LN(C1428/C1427) -> 0.0073269265 | F1427: =YEAR(A1427) -> 2025
A1428: 46022 | B1428: 2791.2 | C1428: 26129.6 | F1428: =YEAR(A1428) -> 2025

Sheet EVA & MVA
A1: Particulars | B1: FY25 | C1: FY24 | D1: FY23 | E1: FY22 | F1: FY21 | G1: FY20 | H1: (₹ in Millions)
A2: NOPAT | B2: 15799.021 | C2: 14307.287 | D2: 15424.418 | E2: 13371.966 | F2: 11334.688 | G2: 10894.064
A4: WACC | B4: 0.1263 | C4: 0.1336 | D4: 0.1433 | E4: 0.1331 | F4: 0.1285 | G4: 0.1224
A6: Capital Invested (Book Value) | B6: ='Balance Sheet'!C38+'FCFF & FCFE'!B27 -> 118469.79 | C6: ='Balance Sheet'!D38+'FCFF & FCFE'!C27 -> 105366.43 | D6: ='Balance Sheet'!E38+'FCFF & FCFE'!D27 -> 88148.97 | E6: ='Balance Sheet'!F38+'FCFF & FCFE'!E27 -> 81550.35 | F6: ='Balance Sheet'!G38+'FCFF & FCFE'!F27 -> 76309.12 | G6: ='Balance Sheet'!H38+'FCFF & FCFE'!G27 -> 71249.84
A8: EVA | B8: =B2-(B4*B6) -> 836.28684 | C8: =C2-(C4*C6) -> 230.33146 | D8: =D2-(D4*D6) -> 2792.6703 | E8: =E2-(E4*E6) -> 2517.6145 | F8: =F2-(F4*F6) -> 1528.9665 | G8: =G2-(G4*G6) -> 2173.0837
A10: Equity Share Capital | B10: 1900.84 | C10: 1890.05 | D10: 1884.07 | E10: 1878.25 | F10: 1870.49 | G10: 1865.43
A11: Face Value (FV) | B11: 10 | C11: 10 | D11: 10 | E11: 10 | F11: 10 | G11: 10
A12: Shares Outstanding (M) | B12: 190.08 | C12: 189.01 | D12: 188.41 | E12: 187.83 | F12: 187.05 | G12: 186.54
A13: CMP (31-Mar Price) | B13: 2500.2 | C13: 2388.05 | D13: 1795.75 | E13: 3376.85 | F13: 1760.48 | G13: 675.65
A14: Market Value of Equity | B14: =B12*B13 -> 475238.02 | C14: =C12*C13 -> 451365.33 | D14: =D12*D13 -> 338337.26 | E14: =E12*E13 -> 634273.74 | F14: =F12*F13 -> 329297.78 | G14: =G12*G13 -> 126035.75
A15: BV of Owners' Equity | B15: ='Balance Sheet'!C38 -> 96283.96 | C15: ='Balance Sheet'!D38 -> 87946 | D15: ='Balance Sheet'!E38 -> 79348.39 | E15: ='Balance Sheet'!F38 -> 69431.31 | F15: ='Balance Sheet'!G38 -> 65267.1 | G15: ='Balance Sheet'!H38 -> 58295.99
A17: MVA | B17: =B14-B15 -> 378954.06 | C17: =C14-C15 -> 363419.33 | D17: =D14-D15 -> 258988.87 | E17: =E14-E15 -> 564842.43 | F17: =F14-F15 -> 264030.68 | G17: =G14-G15 -> 67739.761

Sheet Interpretation
A1: FCFF (Free Cash Flow to Firm)
A3: FCFF represents cash available to all capital providers both debt and equity holders after operating expenses and reinvestment. Mphasis shows strong and consistent FCFF generation across all six years (FY20–FY25). The FY24 spike to ₹21,733M was driven by a favorable swing in working capital (+₹4,028M). FY25 normalized to ₹17,630M, which still comfortably exceeds earlier years. This consistency confirms Mphasis's asset-light business model and operational efficiency, making it a highly cash-generative firm relative to its investment needs.
A12: FCFE (Free Cash Flow to Equity)
A14: FCFE represents cash left for equity shareholders after debt obligations are met. The FY24 number (₹35,709M) is an outlier inflated by a large net debt increase of ₹12,965M (new borrowings for acquisitions). Stripping that out, the underlying FCFE in FY24 would have been roughly ₹22,744M. FY25 FCFE of ₹14,371M is more representative of sustainable equity cash generation, broadly in line with net income of ₹17,021M after reinvestment needs.
A23: EVA (Economic Value Added)
A25: EVA = NOPAT − (WACC × Capital Invested). A positive EVA means the company earns returns above its cost of capital. Mphasis has positive EVA in all years, confirming genuine value creation. However, EVA compressed dramatically in FY24 (just ₹230M) because WACC rose to 14.3% (its highest in the period) while capital employed surged due to acquisitions. In FY25, EVA recovered to ₹836M as WACC eased to 12.6%, though it remains well below the FY23 peak of ₹2,793M. The declining trend from FY23 onward signals that the rate of value creation is slowing as the capital base grows faster than NOPAT.
A37: MVA (Market Value Added)
A39: MVA = Market Value of Equity Book Value of Equity. It captures how much value the market believes the company has created beyond the capital shareholders invested. MVA grew nearly 5.6× from ₹67,740M in FY20 to ₹378,954M in FY25, driven by a surge in the share price from ₹675 to ₹2,500. The FY22 peak of ₹564,842M coincided with the tech-sector euphoria. The decline from FY22 despite improving book value reflects the broader IT sector de-rating as interest rates rose globally. The current FY25 MVA of ~₹3.79 lakh crore still signals strong market confidence in the company's future earnings potential.

Sheet Activity Ratios
A1: Particulars | B1: Industry avg | C1: 45747 | D1: Industry avg | E1: 45382 | F1: Industry avg | G1: 45016 | H1: Industry avg | I1: 44651 | J1: Industry avg | K1: 44286
A2: Net Sales | C2: ='Income Statement'!B3 -> 142299.87 | E2: ='Income Statement'!C3 -> 132785.15 | G2: ='Income Statement'!D3 -> 137984.97 | I2: ='Income Statement'!E3 -> 119614.44 | K2: ='Income Statement'!F3 -> 97223.11 | N2: Company operates in service industry; hence inventory is negligible.
A3: Avg Receivables | C3: =('Balance Sheet'!C23+'Balance Sheet'!D23)/2 -> 26331.44 | E3: =('Balance Sheet'!D23+'Balance Sheet'!E23)/2 -> 24730.975 | G3: =('Balance Sheet'!E23+'Balance Sheet'!F24+'Balance Sheet'!F25)/2 -> 23737.84 | I3: =('Balance Sheet'!G24+'Balance Sheet'!G25+'Balance Sheet'!F24+'Balance Sheet'!F25)/2 -> 20387.115 | K3: =('Balance Sheet'!G24+'Balance Sheet'!G25+'Balance Sheet'!H23+'Balance Sheet'!H25)/2 -> 18100.205
A4: Receivable Turnover | B4: 4.71 | C4: =C2/C3 -> 5.4041811 | D4: 4.66 | E4: =E2/E3 -> 5.3691838 | F4: 4.86 | G4: =G2/G3 -> 5.8128697 | H4: 4.85 | I4: =I2/I3 -> 5.8671587 | J4: 4.34 | K4: =K2/K3 -> 5.3713817
A5: Net Purchases | C5: ='Income Statement'!B12-('Income Statement'!B8+'Income Statement'!B10) -> 36038.49 | E5: ='Income Statement'!C12-('Income Statement'!C8+'Income Statement'!C10) -> 30921.71 | G5: ='Income Statement'!D12-('Income Statement'!D8+'Income Statement'!D10) -> 33860.17 | I5: ='Income Statement'!E12-('Income Statement'!E8+'Income Statement'!E10) -> 28837.41 | K5: ='Income Statement'!F12-('Income Statement'!F8+'Income Statement'!F10) -> 23530.74
A6: Avg Payables | C6: =('Balance Sheet'!C52+'Balance Sheet'!D52)/2 -> 8883.9 | E6: =('Balance Sheet'!D52+'Balance Sheet'!E52)/2 -> 8311.64 | G6: =('Balance Sheet'!E52+'Balance Sheet'!F52)/2 -> 8568.035 | I6: =('Balance Sheet'!F52+'Balance Sheet'!G52)/2 -> 7229.94 | K6: =('Balance Sheet'!G52+'Balance Sheet'!H52)/2 -> 6315.385
A7: Payable Turnover | B7: 8.7 | C7: =C5/C6 -> 4.0566069 | D7: 8.54 | E7: =E5/E6 -> 3.7202899 | F7: 8.67 | G7: =G5/G6 -> 3.9519178 | H7: 8.73 | I7: =I5/I6 -> 3.9886099 | J7: 8.06 | K7: =K5/K6 -> 3.7259391
A8: DSO (Days sales o/s) | B8: 77.44 | C8: =365/C4 -> 67.540298 | D8: 78.36 | E8: =365/E4 -> 67.980538 | F8: 75.14 | G8: =365/G4 -> 62.791706 | H8: 75.19 | I8: =365/I4 -> 62.210691 | J8: 84.12 | K8: =365/K4 -> 67.952721
A9: DPO (Days payable o/s) | B9: 41.95 | C9: =365/C7 -> 89.976675 | D9: 42.74 | E9: =365/E7 -> 98.110635 | F9: 42.11 | G9: =365/G7 -> 92.360221 | H9: 41.82 | I9: =365/I7 -> 91.510579 | J9: 45.25 | K9: =365/K7 -> 97.96188
A11: CCC (Cash Conversion Cycle) | B11: 36.28 | C11: =C8-C9 -> -22.436377 | D11: 37.57 | E11: =E8-E9 -> -30.130097 | F11: 35.06 | G11: =G8-G9 -> -29.568515 | H11: 35.18 | I11: =I8-I9 -> -29.299888 | J11: 40.66 | K11: =K8-K9 -> -30.009159
